Workbook

Sheet Sample ID
D2: Complete this first | H2: Assay ID
D5: No | E5: Sample Description | F5: Diluton Factor | H5: Date | I5: 45975 | W5: 12
D6: A 1-6 | E6: 484 | F6: 1 | H6: AssayID | I6: 48h
D7: B 1-6 | E7: 548 | F7: 1 | H7: CultNo | I7: -
D8: C1-6 | E8: 716 | F8: 1 | H8: Supernatant Treatment | I8: NA
D9: D 1-6 | E9: 824 | F9: 1 | H9: PlasticType | I9: PCL (6.9mg/ml)
D10: E 1-6 | E10: 437 | F10: 1 | H10: Yeast | I10: D8T3
D11: F 1-6 | F11: 0 | H11: Media | I11: CSL (different cultivations combined)
D12: G 1-6 | F12: 0
D13: H 1-6 | F13: 0 | H13: Notes
D14: A 7-12 | F14: 0
D15: B 7-12 | F15: 0 | H15: Checking activity of new cultivation in CSL media compared to a concentrate
D16: C7-12 | F16: 0
D17: D 7-12
D18: E 7-12
D19: F 7-12
D20: G 7-12
D21: H 7-12
D24: Labelling Convention | H24: Reslts
D26: Each well on the 96-well plate is labeled according to this structure: Sx_By_Tz | H26: Concentration worked delivering final activity of ~5U/mL
D32: x = sample number (e.g., S1 = YPD 48h 60x, S2 = control)
D34: y = biological replicate number (1–3)
D36: z = technical replicate number (1–2)

Sheet Data
A2: User: USER
A3: Path: C:\Program Files (x86)\BMG\SPECTROstar Nano\User\Data
A4: Test ID: 87
A5: Test Name: Polyesterase assay_Kinetic
A6: Date: 2025/11/25
A7: Time: 13:35:44
A8: Absorbance | D8: Absorbance values are displayed as OD
A12: Cycle 1 (0 min)
B13: Raw Data (595)
B14: 1 | C14: 2 | D14: 3 | E14: 4 | F14: 5 | G14: 6 | H14: 7 | I14: 8 | J14: 9 | K14: 10 | L14: 11 | M14: 12
A15: A | B15: 1.971 | C15: 1.97 | D15: 1.999 | E15: 1.971 | F15: 1.97 | G15: 1.999
A16: B | B16: 1.963 | C16: 1.96 | D16: 1.972 | E16: 1.963 | F16: 1.96 | G16: 1.972
A17: C | B17: 1.979 | C17: 2 | D17: 2.027 | E17: 1.979 | F17: 2 | G17: 2.027
A18: D | B18: 2.05 | C18: 2.047 | D18: 2.055 | E18: 2.05 | F18: 2.047 | G18: 2.055
A19: E | B19: 2.091 | C19: 2.067 | D19: 2.089 | E19: 2.091 | F19: 2.067 | G19: 2.089
A20: F | B20: 1.897 | C20: 1.934 | D20: 1.895 | E20: 1.897 | F20: 1.934 | G20: 1.895
A21: G | B21: 1.907 | C21: 1.902 | D21: 1.914 | E21: 1.907 | F21: 1.902 | G21: 1.914
A22: H
A24: Cycle 2 (5 min)
B25: Raw Data (595) | E25: Raw Data (595)
B26: 1 | C26: 2 | D26: 3 | E26: 1 | F26: 2 | G26: 3 | H26: 7 | I26: 8 | J26: 9 | K26: 10 | L26: 11 | M26: 12
A27: A | B27: 1.959 | C27: 1.955 | D27: 1.977 | E27: 1.959 | F27: 1.955 | G27: 1.977
A28: B | B28: 1.972 | C28: 1.983 | D28: 1.989 | E28: 1.972 | F28: 1.983 | G28: 1.989
A29: C | B29: 1.985 | C29: 2.005 | D29: 2.019 | E29: 1.985 | F29: 2.005 | G29: 2.019
A30: D | B30: 2.154 | C30: 2.149 | D30: 2.159 | E30: 2.154 | F30: 2.149 | G30: 2.159
A31: E | B31: 2.154 | C31: 2.142 | D31: 2.128 | E31: 2.154 | F31: 2.142 | G31: 2.128
A32: F | B32: 1.838 | C32: 1.883 | D32: 1.844 | E32: 1.838 | F32: 1.883 | G32: 1.844
A33: G | B33: 1.871 | C33: 1.88 | D33: 1.89 | E33: 1.871 | F33: 1.88 | G33: 1.89
A34: H
A36: Cycle 3 (10 min)
B37: Raw Data (595) | E37: Raw Data (595)
B38: 1 | C38: 2 | D38: 3 | E38: 1 | F38: 2 | G38: 3 | H38: 7 | I38: 8 | J38: 9 | K38: 10 | L38: 11 | M38: 12
A39: A | B39: 1.963 | C39: 1.956 | D39: 1.986 | E39: 1.963 | F39: 1.956 | G39: 1.986
A40: B | B40: 1.984 | C40: 1.998 | D40: 2.007 | E40: 1.984 | F40: 1.998 | G40: 2.007
A41: C | B41: 2.001 | C41: 2.018 | D41: 2.027 | E41: 2.001 | F41: 2.018 | G41: 2.027
A42: D | B42: 2.197 | C42: 2.218 | D42: 2.204 | E42: 2.197 | F42: 2.218 | G42: 2.204
A43: E | B43: 2.171 | C43: 2.161 | D43: 2.167 | E43: 2.171 | F43: 2.161 | G43: 2.167
A44: F | B44: 1.783 | C44: 1.823 | D44: 1.773 | E44: 1.783 | F44: 1.823 | G44: 1.773
A45: G | B45: 1.856 | C45: 1.851 | D45: 1.871 | E45: 1.856 | F45: 1.851 | G45: 1.871
A46: H
...

Sheet Results
C4: OD Readings (Raw Data) Do not edit | L4: Standard Curve Intergration | W4: Change in Substrate Concentration | AG4: Activity (mg/ml/min)
L6: Substrate concentration (mg/ml) y = (OD - c)/m | W6: Change in Substrate Concentration (SC) per minute | AG6: Correct for supernatant dilution factor
L10: Do NOT adjust dilution factor. It willl autopopulate from Sample ID sheet | N10: Gradient | O10: m | P10: ='Std Curve'!D19 -> 1.0245333 | W10: Δ SC (mg/mlmin) = (SCT0 - SCTx)/Tx | AG10: Δ SC/min x Dilution Correction Factor
N11: y-asymptote | O11: c | P11: ='Std Curve'!D20 -> 0.19706667
C13: 0 | E13: 1 | F13: 2 | G13: 3 | H13: 4 | I13: 5 | J13: 6 | L13: 0 | N13: 1 | O13: 2 | P13: 3 | Q13: 4 | R13: 5 | S13: 6 | T13: Average SC (mg/ml) | U13: Std Dev | W13: Time (min) | X13: 1 | Y13: 2 | Z13: 3 | AA13: 4 | AB13: 5 | AC13: 6 | AD13: Average Δ SC (mg/ml/min) | AE13: Std Dev | AG13: 0 | AH13: Dilution factor | AO13: Activity (mg/ml/min) | AP13: Std Dev
D14: A | E14: =Data!B15 -> 1.971 | F14: =Data!C15 -> 1.97 | G14: =Data!D15 -> 1.999 | H14: =Data!E15 -> 1.971 | I14: =Data!F15 -> 1.97 | J14: =Data!G15 -> 1.999 | M14: A | N14: =IF(((E14-$P$11)/$P$10)>0,((E14-$P$11)/$P$10)," ") -> 1.731455 | O14: =IF(((F14-$P$11)/$P$10)>0,((F14-$P$11)/$P$10)," ") -> 1.7304789 | P14: =IF(((G14-$P$11)/$P$10)>0,((G14-$P$11)/$P$10)," ") -> 1.7587845 | Q14: =IF(((H14-$P$11)/$P$10)>0,((H14-$P$11)/$P$10)," ") -> 1.731455 | R14: =IF(((I14-$P$11)/$P$10)>0,((I14-$P$11)/$P$10)," ") -> 1.7304789 | S14: =IF(((J14-$P$11)/$P$10)>0,((J14-$P$11)/$P$10)," ") -> 1.7587845 | T14: =IFERROR(AVERAGE(N14:S14),"") -> 1.7402395 | U14: =IFERROR(STDEV(N14:S14),"") -> 0.014371548 | W14: 0 | AH14: ='Sample ID'!$F$6 -> 1 | AI14: =IFERROR((X14*$AH$14),"") -> 0 | AJ14: =IFERROR((Y14*$AH$14),"") -> 0 | AK14: =IFERROR((Z14*$AH$14),"") -> 0 | AL14: =IFERROR((AA14*$AH$14),"") -> 0 | AM14: =IFERROR((AB14*$AH$14),"") -> 0 | AN14: =IFERROR((AC14*$AH$14),"") -> 0 | AO14: =IFERROR(AD14*AH14,"") -> 0
D15: B | E15: =Data!B16 -> 1.963 | F15: =Data!C16 -> 1.96 | G15: =Data!D16 -> 1.972 | H15: =Data!E16 -> 1.963 | I15: =Data!F16 -> 1.96 | J15: =Data!G16 -> 1.972 | M15: B | N15: =IF(((E15-$P$11)/$P$10)>0,((E15-$P$11)/$P$10)," ") -> 1.7236465 | O15: =IF(((F15-$P$11)/$P$10)>0,((F15-$P$11)/$P$10)," ") -> 1.7207184 | P15: =IF(((G15-$P$11)/$P$10)>0,((G15-$P$11)/$P$10)," ") -> 1.732431 | Q15: =IF(((H15-$P$11)/$P$10)>0,((H15-$P$11)/$P$10)," ") -> 1.7236465 | R15: =IF(((I15-$P$11)/$P$10)>0,((I15-$P$11)/$P$10)," ") -> 1.7207184 | S15: =IF(((J15-$P$11)/$P$10)>0,((J15-$P$11)/$P$10)," ") -> 1.732431 | T15: =IFERROR(AVERAGE(N15:S15),"") -> 1.7255986 | U15: =IFERROR(STDEV(N15:S15),"") -> 0.0054519417 | W15: 0 | AH15: ='Sample ID'!$F$7 -> 1 | AI15: =IFERROR((X15*$AH$15),"") -> 0 | AJ15: =IFERROR((Y15*$AH$15),"") -> 0 | AK15: =IFERROR((Z15*$AH$15),"") -> 0 | AL15: =IFERROR((AA15*$AH$15),"") -> 0 | AM15: =IFERROR((AB15*$AH$15),"") -> 0 | AN15: =IFERROR((AC15*$AH$15),"") -> 0 | AO15: =IFERROR(AD15*AH15,"") -> 0
D16: C | E16: =Data!B17 -> 1.979 | F16: =Data!C17 -> 2 | G16: =Data!D17 -> 2.027 | H16: =Data!E17 -> 1.979 | I16: =Data!F17 -> 2 | J16: =Data!G17 -> 2.027 | M16: C | N16: =IF(((E16-$P$11)/$P$10)>0,((E16-$P$11)/$P$10)," ") -> 1.7392634 | O16: =IF(((F16-$P$11)/$P$10)>0,((F16-$P$11)/$P$10)," ") -> 1.7597605 | P16: =IF(((G16-$P$11)/$P$10)>0,((G16-$P$11)/$P$10)," ") -> 1.786114 | Q16: =IF(((H16-$P$11)/$P$10)>0,((H16-$P$11)/$P$10)," ") -> 1.7392634 | R16: =IF(((I16-$P$11)/$P$10)>0,((I16-$P$11)/$P$10)," ") -> 1.7597605 | S16: =IF(((J16-$P$11)/$P$10)>0,((J16-$P$11)/$P$10)," ") -> 1.786114 | T16: =IFERROR(AVERAGE(N16:S16),"") -> 1.7617126 | U16: =IFERROR(STDEV(N16:S16),"") -> 0.021006717 | W16: 0 | AH16: ='Sample ID'!$F$8 -> 1 | AI16: =IFERROR((X16*$AH$16),"") -> 0 | AJ16: =IFERROR((Y16*$AH$16),"") -> 0 | AK16: =IFERROR((Z16*$AH$16),"") -> 0 | AL16: =IFERROR((AA16*$AH$16),"") -> 0 | AM16: =IFERROR((AB16*$AH$16),"") -> 0 | AN16: =IFERROR((AC16*$AH$16),"") -> 0 | AO16: =IFERROR(AD16*AH16,"") -> 0
D17: D | E17: =Data!B18 -> 2.05 | F17: =Data!C18 -> 2.047 | G17: =Data!D18 -> 2.055 | H17: =Data!E18 -> 2.05 | I17: =Data!F18 -> 2.047 | J17: =Data!G18 -> 2.055 | M17: D | N17: =IF(((E17-$P$11)/$P$10)>0,((E17-$P$11)/$P$10)," ") -> 1.8085632 | O17: =IF(((F17-$P$11)/$P$10)>0,((F17-$P$11)/$P$10)," ") -> 1.8056351 | P17: =IF(((G17-$P$11)/$P$10)>0,((G17-$P$11)/$P$10)," ") -> 1.8134435 | Q17: =IF(((H17-$P$11)/$P$10)>0,((H17-$P$11)/$P$10)," ") -> 1.8085632 | R17: =IF(((I17-$P$11)/$P$10)>0,((I17-$P$11)/$P$10)," ") -> 1.8056351 | S17: =IF(((J17-$P$11)/$P$10)>0,((J17-$P$11)/$P$10)," ") -> 1.8134435 | T17: =IFERROR(AVERAGE(N17:S17),"") -> 1.809214 | U17: =IFERROR(STDEV(N17:S17),"") -> 0.0035282253 | W17: 0 | AH17: ='Sample ID'!$F$9 -> 1 | AI17: =IFERROR((X17*$AH$17),"") -> 0 | AJ17: =IFERROR((Y17*$AH$17),"") -> 0 | AK17: =IFERROR((Z17*$AH$17),"") -> 0 | AL17: =IFERROR((AA17*$AH$17),"") -> 0 | AM17: =IFERROR((AB17*$AH$17),"") -> 0 | AN17: =IFERROR((AC17*$AH$17),"") -> 0 | AO17: =IFERROR(AD17*AH17,"") -> 0
D18: E | E18: =Data!B19 -> 2.091 | F18: =Data!C19 -> 2.067 | G18: =Data!D19 -> 2.089 | H18: =Data!E19 -> 2.091 | I18: =Data!F19 -> 2.067 | J18: =Data!G19 -> 2.089 | M18: E | N18: =IF(((E18-$P$11)/$P$10)>0,((E18-$P$11)/$P$10)," ") -> 1.8485815 | O18: =IF(((F18-$P$11)/$P$10)>0,((F18-$P$11)/$P$10)," ") -> 1.8251562 | P18: =IF(((G18-$P$11)/$P$10)>0,((G18-$P$11)/$P$10)," ") -> 1.8466294 | Q18: =IF(((H18-$P$11)/$P$10)>0,((H18-$P$11)/$P$10)," ") -> 1.8485815 | R18: =IF(((I18-$P$11)/$P$10)>0,((I18-$P$11)/$P$10)," ") -> 1.8251562 | S18: =IF(((J18-$P$11)/$P$10)>0,((J18-$P$11)/$P$10)," ") -> 1.8466294 | T18: =IFERROR(AVERAGE(N18:S18),"") -> 1.8401223 | U18: =IFERROR(STDEV(N18:S18),"") -> 0.011625566 | W18: 0 | AH18: ='Sample ID'!$F$10 -> 1 | AI18: =IFERROR((X18*$AH$18),"") -> 0 | AJ18: =IFERROR((Y18*$AH$18),"") -> 0 | AK18: =IFERROR((Z18*$AH$18),"") -> 0 | AL18: =IFERROR((AA18*$AH$18),"") -> 0 | AM18: =IFERROR((AB18*$AH$18),"") -> 0 | AN18: =IFERROR((AC18*$AH$18),"") -> 0 | AO18: =IFERROR(AD18*AH18,"") -> 0
D19: F | E19: =Data!B20 -> 1.897 | F19: =Data!C20 -> 1.934 | G19: =Data!D20 -> 1.895 | H19: =Data!E20 -> 1.897 | I19: =Data!F20 -> 1.934 | J19: =Data!G20 -> 1.895 | M19: F | N19: =IF(((E19-$P$11)/$P$10)>0,((E19-$P$11)/$P$10)," ") -> 1.659227 | O19: =IF(((F19-$P$11)/$P$10)>0,((F19-$P$11)/$P$10)," ") -> 1.695341 | P19: =IF(((G19-$P$11)/$P$10)>0,((G19-$P$11)/$P$10)," ") -> 1.6572749 | Q19: =IF(((H19-$P$11)/$P$10)>0,((H19-$P$11)/$P$10)," ") -> 1.659227 | R19: =IF(((I19-$P$11)/$P$10)>0,((I19-$P$11)/$P$10)," ") -> 1.695341 | S19: =IF(((J19-$P$11)/$P$10)>0,((J19-$P$11)/$P$10)," ") -> 1.6572749 | T19: =IFERROR(AVERAGE(N19:S19),"") -> 1.6706143 | U19: =IFERROR(STDEV(N19:S19),"") -> 0.019173109 | W19: 0 | AH19: ='Sample ID'!$F$11 -> 0 | AI19: =IFERROR((X19*$AH$19),"") -> 0 | AJ19: =IFERROR((Y19*$AH$19),"") -> 0 | AK19: =IFERROR((Z19*$AH$19),"") -> 0 | AL19: =IFERROR((AA19*$AH$19),"") -> 0 | AM19: =IFERROR((AB19*$AH$19),"") -> 0 | AN19: =IFERROR((AC19*$AH$19),"") -> 0 | AO19: =IFERROR(AD19*AH19,"") -> 0
D20: G | E20: =Data!B21 -> 1.907 | F20: =Data!C21 -> 1.902 | G20: =Data!D21 -> 1.914 | H20: =Data!E21 -> 1.907 | I20: =Data!F21 -> 1.902 | J20: =Data!G21 -> 1.914 | M20: G | N20: =IF(((E20-$P$11)/$P$10)>0,((E20-$P$11)/$P$10)," ") -> 1.6689875 | O20: =IF(((F20-$P$11)/$P$10)>0,((F20-$P$11)/$P$10)," ") -> 1.6641072 | P20: =IF(((G20-$P$11)/$P$10)>0,((G20-$P$11)/$P$10)," ") -> 1.6758199 | Q20: =IF(((H20-$P$11)/$P$10)>0,((H20-$P$11)/$P$10)," ") -> 1.6689875 | R20: =IF(((I20-$P$11)/$P$10)>0,((I20-$P$11)/$P$10)," ") -> 1.6641072 | S20: =IF(((J20-$P$11)/$P$10)>0,((J20-$P$11)/$P$10)," ") -> 1.6758199 | T20: =IFERROR(AVERAGE(N20:S20),"") -> 1.6696382 | U20: =IFERROR(STDEV(N20:S20),"") -> 0.0052622506 | W20: 0 | AH20: ='Sample ID'!$F$12 -> 0 | AI20: =IFERROR((X20*$AH$20),"") -> 0 | AJ20: =IFERROR((Y20*$AH$20),"") -> 0 | AK20: =IFERROR((Z20*$AH$20),"") -> 0 | AL20: =IFERROR((AA20*$AH$20),"") -> 0 | AM20: =IFERROR((AB20*$AH$20),"") -> 0 | AN20: =IFERROR((AC20*$AH$20),"") -> 0 | AO20: =IFERROR(AD20*AH20,"") -> 0
D21: H | E21: =Data!B22 -> 0 | F21: =Data!C22 -> 0 | G21: =Data!D22 -> 0 | H21: =Data!E22 -> 0 | I21: =Data!F22 -> 0 | J21: =Data!G22 -> 0 | M21: H | N21: =IF(((E21-$P$11)/$P$10)>0,((E21-$P$11)/$P$10)," ") | O21: =IF(((F21-$P$11)/$P$10)>0,((F21-$P$11)/$P$10)," ") | P21: =IF(((G21-$P$11)/$P$10)>0,((G21-$P$11)/$P$10)," ") | Q21: =IF(((H21-$P$11)/$P$10)>0,((H21-$P$11)/$P$10)," ") | R21: =IF(((I21-$P$11)/$P$10)>0,((I21-$P$11)/$P$10)," ") | S21: =IF(((J21-$P$11)/$P$10)>0,((J21-$P$11)/$P$10)," ") | T21: =IFERROR(AVERAGE(N21:S21),"") | U21: =IFERROR(STDEV(N21:S21),"") | W21: 0 | AH21: ='Sample ID'!$F$13 -> 0 | AI21: =IFERROR((X21*$AH$21),"") -> 0 | AJ21: =IFERROR((Y21*$AH$21),"") -> 0 | AK21: =IFERROR((Z21*$AH$21),"") -> 0 | AL21: =IFERROR((AA21*$AH$21),"") -> 0 | AM21: =IFERROR((AB21*$AH$21),"") -> 0 | AN21: =IFERROR((AC21*$AH$21),"") -> 0 | AO21: =IFERROR(AD21*AH21,"") -> 0
E22: 7 | F22: 8 | G22: 9 | H22: 10 | I22: 11 | J22: 12 | N22: 7 | O22: 8 | P22: 9 | Q22: 10 | R22: 11 | S22: 12 | T22: Average SC (mg/ml) | U22: Std Dev | X22: 7 | Y22: 8 | Z22: 9 | AA22: 10 | AB22: 11 | AC22: 12 | AD22: Average Δ SC (mg/ml/min) | AE22: Std Dev | AP22: Std Dev
D23: A | E23: =Data!H15 -> 0 | F23: =Data!I15 -> 0 | G23: =Data!J15 -> 0 | H23: =Data!K15 -> 0 | I23: =Data!L15 -> 0 | J23: =Data!M15 -> 0 | M23: A | N23: =IF(((E23-$P$11)/$P$10)>0,((E23-$P$11)/$P$10)," ") | O23: =IF(((F23-$P$11)/$P$10)>0,((F23-$P$11)/$P$10)," ") | P23: =IF(((G23-$P$11)/$P$10)>0,((G23-$P$11)/$P$10)," ") | Q23: =IF(((H23-$P$11)/$P$10)>0,((H23-$P$11)/$P$10)," ") | R23: =IF(((I23-$P$11)/$P$10)>0,((I23-$P$11)/$P$10)," ") | S23: =IF(((J23-$P$11)/$P$10)>0,((J23-$P$11)/$P$10)," ") | T23: =IFERROR(AVERAGE(N23:S23),"") | U23: =IFERROR(STDEV(N23:S23),"") | W23: 0 | AH23: ='Sample ID'!$F$14 -> 0 | AI23: =IFERROR((X23*$AH$23),"") -> 0 | AJ23: =IFERROR((Y23*$AH$23),"") -> 0 | AK23: =IFERROR((Z23*$AH$23),"") -> 0 | AL23: =IFERROR((AA23*$AH$23),"") -> 0 | AM23: =IFERROR((AB23*$AH$23),"") -> 0 | AN23: =IFERROR((AC23*$AH$23),"") -> 0 | AO23: =IFERROR(AD23*AH23,"") -> 0
D24: B | E24: =Data!H16 -> 0 | F24: =Data!I16 -> 0 | G24: =Data!J16 -> 0 | H24: =Data!K16 -> 0 | I24: =Data!L16 -> 0 | J24: =Data!M16 -> 0 | M24: B | N24: =IF(((E24-$P$11)/$P$10)>0,((E24-$P$11)/$P$10)," ") | O24: =IF(((F24-$P$11)/$P$10)>0,((F24-$P$11)/$P$10)," ") | P24: =IF(((G24-$P$11)/$P$10)>0,((G24-$P$11)/$P$10)," ") | Q24: =IF(((H24-$P$11)/$P$10)>0,((H24-$P$11)/$P$10)," ") | R24: =IF(((I24-$P$11)/$P$10)>0,((I24-$P$11)/$P$10)," ") | S24: =IF(((J24-$P$11)/$P$10)>0,((J24-$P$11)/$P$10)," ") | T24: =IFERROR(AVERAGE(N24:S24),"") | U24: =IFERROR(STDEV(N24:S24),"") | W24: 0 | AH24: ='Sample ID'!$F$15 -> 0 | AI24: =IFERROR((X24*$AH$24),"") -> 0 | AJ24: =IFERROR((Y24*$AH$24),"") -> 0 | AK24: =IFERROR((Z24*$AH$24),"") -> 0 | AL24: =IFERROR((AA24*$AH$24),"") -> 0 | AM24: =IFERROR((AB24*$AH$24),"") -> 0 | AN24: =IFERROR((AC24*$AH$24),"") -> 0 | AO24: =IFERROR(AD24*AH24,"") -> 0
D25: C | E25: =Data!H17 -> 0 | F25: =Data!I17 -> 0 | G25: =Data!J17 -> 0 | H25: =Data!K17 -> 0 | I25: =Data!L17 -> 0 | J25: =Data!M17 -> 0 | M25: C | N25: =IF(((E25-$P$11)/$P$10)>0,((E25-$P$11)/$P$10)," ") | O25: =IF(((F25-$P$11)/$P$10)>0,((F25-$P$11)/$P$10)," ") | P25: =IF(((G25-$P$11)/$P$10)>0,((G25-$P$11)/$P$10)," ") | Q25: =IF(((H25-$P$11)/$P$10)>0,((H25-$P$11)/$P$10)," ") | R25: =IF(((I25-$P$11)/$P$10)>0,((I25-$P$11)/$P$10)," ") | S25: =IF(((J25-$P$11)/$P$10)>0,((J25-$P$11)/$P$10)," ") | T25: =IFERROR(AVERAGE(N25:S25),"") | U25: =IFERROR(STDEV(N25:S25),"") | W25: 0 | AH25: ='Sample ID'!$F$16 -> 0 | AI25: =IFERROR((X25*$AH$25),"") -> 0 | AJ25: =IFERROR((Y25*$AH$25),"") -> 0 | AK25: =IFERROR((Z25*$AH$25),"") -> 0 | AL25: =IFERROR((AA25*$AH$25),"") -> 0 | AM25: =IFERROR((AB25*$AH$25),"") -> 0 | AN25: =IFERROR((AC25*$AH$25),"") -> 0 | AO25: =IFERROR(AD25*AH25,"") -> 0
D26: D | E26: =Data!H18 -> 0 | F26: =Data!I18 -> 0 | G26: =Data!J18 -> 0 | H26: =Data!K18 -> 0 | I26: =Data!L18 -> 0 | J26: =Data!M18 -> 0 | M26: D | N26: =IF(((E26-$P$11)/$P$10)>0,((E26-$P$11)/$P$10)," ") | O26: =IF(((F26-$P$11)/$P$10)>0,((F26-$P$11)/$P$10)," ") | P26: =IF(((G26-$P$11)/$P$10)>0,((G26-$P$11)/$P$10)," ") | Q26: =IF(((H26-$P$11)/$P$10)>0,((H26-$P$11)/$P$10)," ") | R26: =IF(((I26-$P$11)/$P$10)>0,((I26-$P$11)/$P$10)," ") | S26: =IF(((J26-$P$11)/$P$10)>0,((J26-$P$11)/$P$10)," ") | T26: =IFERROR(AVERAGE(N26:S26),"") | U26: =IFERROR(STDEV(N26:S26),"") | W26: 0 | AH26: ='Sample ID'!$F$17 -> 0 | AI26: =IFERROR((X26*$AH$26),"") -> 0 | AJ26: =IFERROR((Y26*$AH$26),"") -> 0 | AK26: =IFERROR((Z26*$AH$26),"") -> 0 | AL26: =IFERROR((AA26*$AH$26),"") -> 0 | AM26: =IFERROR((AB26*$AH$26),"") -> 0 | AN26: =IFERROR((AC26*$AH$26),"") -> 0 | AO26: =IFERROR(AD26*AH26,"") -> 0
D27: E | E27: =Data!H19 -> 0 | F27: =Data!I19 -> 0 | G27: =Data!J19 -> 0 | H27: =Data!K19 -> 0 | I27: =Data!L19 -> 0 | J27: =Data!M19 -> 0 | M27: E | N27: =IF(((E27-$P$11)/$P$10)>0,((E27-$P$11)/$P$10)," ") | O27: =IF(((F27-$P$11)/$P$10)>0,((F27-$P$11)/$P$10)," ") | P27: =IF(((G27-$P$11)/$P$10)>0,((G27-$P$11)/$P$10)," ") | Q27: =IF(((H27-$P$11)/$P$10)>0,((H27-$P$11)/$P$10)," ") | R27: =IF(((I27-$P$11)/$P$10)>0,((I27-$P$11)/$P$10)," ") | S27: =IF(((J27-$P$11)/$P$10)>0,((J27-$P$11)/$P$10)," ") | T27: =IFERROR(AVERAGE(N27:S27),"") | U27: =IFERROR(STDEV(N27:S27),"") | W27: 0 | AH27: ='Sample ID'!$F$18 -> 0 | AI27: =IFERROR((X27*$AH$27),"") -> 0 | AJ27: =IFERROR((Y27*$AH$27),"") -> 0 | AK27: =IFERROR((Z27*$AH$27),"") -> 0 | AL27: =IFERROR((AA27*$AH$27),"") -> 0 | AM27: =IFERROR((AB27*$AH$27),"") -> 0 | AN27: =IFERROR((AC27*$AH$27),"") -> 0 | AO27: =IFERROR(AD27*AH27,"") -> 0
D28: F | E28: =Data!H20 -> 0 | F28: =Data!I20 -> 0 | G28: =Data!J20 -> 0 | H28: =Data!K20 -> 0 | I28: =Data!L20 -> 0 | J28: =Data!M20 -> 0 | M28: F | N28: =IF(((E28-$P$11)/$P$10)>0,((E28-$P$11)/$P$10)," ") | O28: =IF(((F28-$P$11)/$P$10)>0,((F28-$P$11)/$P$10)," ") | P28: =IF(((G28-$P$11)/$P$10)>0,((G28-$P$11)/$P$10)," ") | Q28: =IF(((H28-$P$11)/$P$10)>0,((H28-$P$11)/$P$10)," ") | R28: =IF(((I28-$P$11)/$P$10)>0,((I28-$P$11)/$P$10)," ") | S28: =IF(((J28-$P$11)/$P$10)>0,((J28-$P$11)/$P$10)," ") | T28: =IFERROR(AVERAGE(N28:S28),"") | U28: =IFERROR(STDEV(N28:S28),"") | W28: 0 | AH28: ='Sample ID'!$F$19 -> 0 | AI28: =IFERROR((X28*$AH$28),"") -> 0 | AJ28: =IFERROR((Y28*$AH$28),"") -> 0 | AK28: =IFERROR((Z28*$AH$28),"") -> 0 | AL28: =IFERROR((AA28*$AH$28),"") -> 0 | AM28: =IFERROR((AB28*$AH$28),"") -> 0 | AN28: =IFERROR((AC28*$AH$28),"") -> 0 | AO28: =IFERROR(AD28*AH28,"") -> 0
D29: G | E29: =Data!H21 -> 0 | F29: =Data!I21 -> 0 | G29: =Data!J21 -> 0 | H29: =Data!K21 -> 0 | I29: =Data!L21 -> 0 | J29: =Data!M21 -> 0 | M29: G | N29: =IF(((E29-$P$11)/$P$10)>0,((E29-$P$11)/$P$10)," ") | O29: =IF(((F29-$P$11)/$P$10)>0,((F29-$P$11)/$P$10)," ") | P29: =IF(((G29-$P$11)/$P$10)>0,((G29-$P$11)/$P$10)," ") | Q29: =IF(((H29-$P$11)/$P$10)>0,((H29-$P$11)/$P$10)," ") | R29: =IF(((I29-$P$11)/$P$10)>0,((I29-$P$11)/$P$10)," ") | S29: =IF(((J29-$P$11)/$P$10)>0,((J29-$P$11)/$P$10)," ") | T29: =IFERROR(AVERAGE(N29:S29),"") | U29: =IFERROR(STDEV(N29:S29),"") | W29: 0 | AH29: ='Sample ID'!$F$20 -> 0 | AI29: =IFERROR((X29*$AH$29),"") -> 0 | AJ29: =IFERROR((Y29*$AH$29),"") -> 0 | AK29: =IFERROR((Z29*$AH$29),"") -> 0 | AL29: =IFERROR((AA29*$AH$29),"") -> 0 | AM29: =IFERROR((AB29*$AH$29),"") -> 0 | AN29: =IFERROR((AC29*$AH$29),"") -> 0 | AO29: =IFERROR(AD29*AH29,"") -> 0
D30: H | E30: =Data!H22 -> 0 | F30: =Data!I22 -> 0 | G30: =Data!J22 -> 0 | H30: =Data!K22 -> 0 | I30: =Data!L22 -> 0 | J30: =Data!M22 -> 0 | M30: H | N30: =IF(((E30-$P$11)/$P$10)>0,((E30-$P$11)/$P$10)," ") | O30: =IF(((F30-$P$11)/$P$10)>0,((F30-$P$11)/$P$10)," ") | P30: =IF(((G30-$P$11)/$P$10)>0,((G30-$P$11)/$P$10)," ") | Q30: =IF(((H30-$P$11)/$P$10)>0,((H30-$P$11)/$P$10)," ") | R30: =IF(((I30-$P$11)/$P$10)>0,((I30-$P$11)/$P$10)," ") | S30: =IF(((J30-$P$11)/$P$10)>0,((J30-$P$11)/$P$10)," ") | T30: =IFERROR(AVERAGE(N30:S30),"") | U30: =IFERROR(STDEV(N30:S30),"") | W30: 0 | AH30: ='Sample ID'!$F$21 -> 0 | AI30: =IFERROR((X30*$AH$30),"") -> 0 | AJ30: =IFERROR((Y30*$AH$30),"") -> 0 | AK30: =IFERROR((Z30*$AH$30),"") -> 0 | AL30: =IFERROR((AA30*$AH$30),"") -> 0 | AM30: =IFERROR((AB30*$AH$30),"") -> 0 | AN30: =IFERROR((AC30*$AH$30),"") -> 0 | AO30: =IFERROR(AD30*AH30,"") -> 0
C31: 5 | E31: 1 | F31: 2 | G31: 3 | H31: 4 | I31: 5 | J31: 6 | L31: 5 | N31: 1 | O31: 2 | P31: 3 | Q31: 4 | R31: 5 | S31: 6 | T31: Average SC (mg/ml) | U31: Std Dev | W31: Time (min) | X31: 1 | Y31: 2 | Z31: 3 | AA31: 4 | AB31: 5 | AC31: 6 | AD31: Average Δ SC (mg/ml/min) | AE31: Std Dev | AG31: 5 | AH31: Dilution factor | AO31: Activity (mg/ml/min) | AP31: Std Dev
D32: A | E32: =Data!B27 -> 1.959 | F32: =Data!C27 -> 1.955 | G32: =Data!D27 -> 1.977 | H32: =Data!E27 -> 1.959 | I32: =Data!F27 -> 1.955 | J32: =Data!G27 -> 1.977 | M32: A | N32: =IF(((E32-$P$11)/$P$10)>0,((E32-$P$11)/$P$10)," ") -> 1.7197423 | O32: =IF(((F32-$P$11)/$P$10)>0,((F32-$P$11)/$P$10)," ") -> 1.7158381 | P32: =IF(((G32-$P$11)/$P$10)>0,((G32-$P$11)/$P$10)," ") -> 1.7373113 | Q32: =IF(((H32-$P$11)/$P$10)>0,((H32-$P$11)/$P$10)," ") -> 1.7197423 | R32: =IF(((I32-$P$11)/$P$10)>0,((I32-$P$11)/$P$10)," ") -> 1.7158381 | S32: =IF(((J32-$P$11)/$P$10)>0,((J32-$P$11)/$P$10)," ") -> 1.7373113 | T32: =IFERROR(AVERAGE(N32:S32),"") -> 1.7242972 | U32: =IFERROR(STDEV(N32:S32),"") -> 0.010230736 | W32: 5 | X32: =IFERROR(($N$14-N32)/W32,"") -> 0.0023425299 | Y32: =IFERROR(($O$14-O32)/W32,"") -> 0.0029281624 | Z32: =IFERROR(($P$14-P32)/W32,"") -> 0.0042946382 | AA32: =IFERROR(($Q$14-Q32)/W32,"") -> 0.0023425299 | AB32: =IFERROR(($R$14-R32)/W32,"") -> 0.0029281624 | AC32: =IFERROR(($S$14-S32)/W32,"") -> 0.0042946382 | AD32: =IFERROR(AVERAGE(X32:AC32), "") -> 0.0031884435 | AE32: =IFERROR(STDEV(X32:AC32), "") -> 0.00089598722 | AH32: ='Sample ID'!$F$6 -> 1 | AI32: =IFERROR((X32*$AH$32),"") -> 0.0023425299 | AJ32: =IFERROR((Y32*$AH$32),"") -> 0.0029281624 | AK32: =IFERROR((Z32*$AH$32),"") -> 0.0042946382 | AL32: =IFERROR((AA32*$AH$32),"") -> 0.0023425299 | AM32: =IFERROR((AB32*$AH$32),"") -> 0.0029281624 | AN32: =IFERROR((AC32*$AH$32),"") -> 0.0042946382 | AO32: =IFERROR(AD32*AH32,"") -> 0.0031884435 | AP32: =IFERROR(STDEV(AI32:AN32), "") -> 0.00089598722
D33: B | E33: =Data!B28 -> 1.972 | F33: =Data!C28 -> 1.983 | G33: =Data!D28 -> 1.989 | H33: =Data!E28 -> 1.972 | I33: =Data!F28 -> 1.983 | J33: =Data!G28 -> 1.989 | M33: B | N33: =IF(((E33-$P$11)/$P$10)>0,((E33-$P$11)/$P$10)," ") -> 1.732431 | O33: =IF(((F33-$P$11)/$P$10)>0,((F33-$P$11)/$P$10)," ") -> 1.7431676 | P33: =IF(((G33-$P$11)/$P$10)>0,((G33-$P$11)/$P$10)," ") -> 1.7490239 | Q33: =IF(((H33-$P$11)/$P$10)>0,((H33-$P$11)/$P$10)," ") -> 1.732431 | R33: =IF(((I33-$P$11)/$P$10)>0,((I33-$P$11)/$P$10)," ") -> 1.7431676 | S33: =IF(((J33-$P$11)/$P$10)>0,((J33-$P$11)/$P$10)," ") -> 1.7490239 | T33: =IFERROR(AVERAGE(N33:S33),"") -> 1.7415409 | U33: =IFERROR(STDEV(N33:S33),"") -> 0.0075268057 | W33: 5 | X33: =IFERROR(($N$15-N33)/W33,"") -> -0.0017568974 | Y33: =IFERROR(($O$15-O33)/W33,"") -> -0.004489849 | Z33: =IFERROR(($P$15-P33)/W33,"") -> -0.0033185841 | AA33: =IFERROR(($Q$15-Q33)/W33,"") -> -0.0017568974 | AB33: =IFERROR(($R$15-R33)/W33,"") -> -0.004489849 | AC33: =IFERROR(($S$15-S33)/W33,"") -> -0.0033185841 | AD33: =IFERROR(AVERAGE(X33:AC33), "") -> -0.0031884435 | AE33: =IFERROR(STDEV(X33:AC33), "") -> 0.0012263632 | AH33: ='Sample ID'!$F$7 -> 1 | AI33: =IFERROR((X33*$AH$33),"") -> -0.0017568974 | AJ33: =IFERROR((Y33*$AH$33),"") -> -0.004489849 | AK33: =IFERROR((Z33*$AH$33),"") -> -0.0033185841 | AL33: =IFERROR((AA33*$AH$33),"") -> -0.0017568974 | AM33: =IFERROR((AB33*$AH$33),"") -> -0.004489849 | AN33: =IFERROR((AC33*$AH$33),"") -> -0.0033185841 | AO33: =IFERROR(AD33*AH33,"") -> -0.0031884435 | AP33: =IFERROR(STDEV(AI33:AN33), "") -> 0.0012263632
D34: C | E34: =Data!B29 -> 1.985 | F34: =Data!C29 -> 2.005 | G34: =Data!D29 -> 2.019 | H34: =Data!E29 -> 1.985 | I34: =Data!F29 -> 2.005 | J34: =Data!G29 -> 2.019 | M34: C | N34: =IF(((E34-$P$11)/$P$10)>0,((E34-$P$11)/$P$10)," ") -> 1.7451197 | O34: =IF(((F34-$P$11)/$P$10)>0,((F34-$P$11)/$P$10)," ") -> 1.7646408 | P34: =IF(((G34-$P$11)/$P$10)>0,((G34-$P$11)/$P$10)," ") -> 1.7783056 | Q34: =IF(((H34-$P$11)/$P$10)>0,((H34-$P$11)/$P$10)," ") -> 1.7451197 | R34: =IF(((I34-$P$11)/$P$10)>0,((I34-$P$11)/$P$10)," ") -> 1.7646408 | S34: =IF(((J34-$P$11)/$P$10)>0,((J34-$P$11)/$P$10)," ") -> 1.7783056 | T34: =IFERROR(AVERAGE(N34:S34),"") -> 1.7626887 | U34: =IFERROR(STDEV(N34:S34),"") -> 0.014917991 | W34: 5 | X34: =IFERROR(($N$16-N34)/W34,"") -> -0.001171265 | Y34: =IFERROR(($O$16-O34)/W34,"") -> -0.00097605414 | Z34: =IFERROR(($P$16-P34)/W34,"") -> 0.0015616866 | AA34: =IFERROR(($Q$16-Q34)/W34,"") -> -0.001171265 | AB34: =IFERROR(($R$16-R34)/W34,"") -> -0.00097605414 | AC34: =IFERROR(($S$16-S34)/W34,"") -> 0.0015616866 | AD34: =IFERROR(AVERAGE(X34:AC34), "") -> -0.00019521083 | AE34: =IFERROR(STDEV(X34:AC34), "") -> 0.0013636842 | AH34: ='Sample ID'!$F$8 -> 1 | AI34: =IFERROR((X34*$AH$34),"") -> -0.001171265 | AJ34: =IFERROR((Y34*$AH$34),"") -> -0.00097605414 | AK34: =IFERROR((Z34*$AH$34),"") -> 0.0015616866 | AL34: =IFERROR((AA34*$AH$34),"") -> -0.001171265 | AM34: =IFERROR((AB34*$AH$34),"") -> -0.00097605414 | AN34: =IFERROR((AC34*$AH$34),"") -> 0.0015616866 | AO34: =IFERROR(AD34*AH34,"") -> -0.00019521083 | AP34: =IFERROR(STDEV(AI34:AN34), "") -> 0.0013636842
D35: D | E35: =Data!B30 -> 2.154 | F35: =Data!C30 -> 2.149 | G35: =Data!D30 -> 2.159 | H35: =Data!E30 -> 2.154 | I35: =Data!F30 -> 2.149 | J35: =Data!G30 -> 2.159 | M35: D | N35: =IF(((E35-$P$11)/$P$10)>0,((E35-$P$11)/$P$10)," ") -> 1.9100729 | O35: =IF(((F35-$P$11)/$P$10)>0,((F35-$P$11)/$P$10)," ") -> 1.9051926 | P35: =IF(((G35-$P$11)/$P$10)>0,((G35-$P$11)/$P$10)," ") -> 1.9149531 | Q35: =IF(((H35-$P$11)/$P$10)>0,((H35-$P$11)/$P$10)," ") -> 1.9100729 | R35: =IF(((I35-$P$11)/$P$10)>0,((I35-$P$11)/$P$10)," ") -> 1.9051926 | S35: =IF(((J35-$P$11)/$P$10)>0,((J35-$P$11)/$P$10)," ") -> 1.9149531 | T35: =IFERROR(AVERAGE(N35:S35),"") -> 1.9100729 | U35: =IFERROR(STDEV(N35:S35),"") -> 0.0043650468 | W35: 5 | X35: =IFERROR(($N$17-N35)/W35,"") -> -0.020301926 | Y35: =IFERROR(($O$17-O35)/W35,"") -> -0.019911504 | Z35: =IFERROR(($P$17-P35)/W35,"") -> -0.020301926 | AA35: =IFERROR(($Q$17-Q35)/W35,"") -> -0.020301926 | AB35: =IFERROR(($R$17-R35)/W35,"") -> -0.019911504 | AC35: =IFERROR(($S$17-S35)/W35,"") -> -0.020301926 | AD35: =IFERROR(AVERAGE(X35:AC35), "") -> -0.020171786 | AE35: =IFERROR(STDEV(X35:AC35), "") -> 0.00020161288 | AH35: ='Sample ID'!$F$9 -> 1 | AI35: =IFERROR((X35*$AH$35),"") -> -0.020301926 | AJ35: =IFERROR((Y35*$AH$35),"") -> -0.019911504 | AK35: =IFERROR((Z35*$AH$35),"") -> -0.020301926 | AL35: =IFERROR((AA35*$AH$35),"") -> -0.020301926 | AM35: =IFERROR((AB35*$AH$35),"") -> -0.019911504 | AN35: =IFERROR((AC35*$AH$35),"") -> -0.020301926 | AO35: =IFERROR(AD35*AH35,"") -> -0.020171786 | AP35: =IFERROR(STDEV(AI35:AN35), "") -> 0.00020161288
D36: E | E36: =Data!B31 -> 2.154 | F36: =Data!C31 -> 2.142 | G36: =Data!D31 -> 2.128 | H36: =Data!E31 -> 2.154 | I36: =Data!F31 -> 2.142 | J36: =Data!G31 -> 2.128 | M36: E | N36: =IF(((E36-$P$11)/$P$10)>0,((E36-$P$11)/$P$10)," ") -> 1.9100729 | O36: =IF(((F36-$P$11)/$P$10)>0,((F36-$P$11)/$P$10)," ") -> 1.8983602 | P36: =IF(((G36-$P$11)/$P$10)>0,((G36-$P$11)/$P$10)," ") -> 1.8846955 | Q36: =IF(((H36-$P$11)/$P$10)>0,((H36-$P$11)/$P$10)," ") -> 1.9100729 | R36: =IF(((I36-$P$11)/$P$10)>0,((I36-$P$11)/$P$10)," ") -> 1.8983602 | S36: =IF(((J36-$P$11)/$P$10)>0,((J36-$P$11)/$P$10)," ") -> 1.8846955 | T36: =IFERROR(AVERAGE(N36:S36),"") -> 1.8977095 | U36: =IFERROR(STDEV(N36:S36),"") -> 0.011360309 | W36: 5 | X36: =IFERROR(($N$18-N36)/W36,"") -> -0.012298282 | Y36: =IFERROR(($O$18-O36)/W36,"") -> -0.014640812 | Z36: =IFERROR(($P$18-P36)/W36,"") -> -0.0076132223 | AA36: =IFERROR(($Q$18-Q36)/W36,"") -> -0.012298282 | AB36: =IFERROR(($R$18-R36)/W36,"") -> -0.014640812 | AC36: =IFERROR(($S$18-S36)/W36,"") -> -0.0076132223 | AD36: =IFERROR(AVERAGE(X36:AC36), "") -> -0.011517439 | AE36: =IFERROR(STDEV(X36:AC36), "") -> 0.0032005052 | AH36: ='Sample ID'!$F$10 -> 1 | AI36: =IFERROR((X36*$AH$36),"") -> -0.012298282 | AJ36: =IFERROR((Y36*$AH$36),"") -> -0.014640812 | AK36: =IFERROR((Z36*$AH$36),"") -> -0.0076132223 | AL36: =IFERROR((AA36*$AH$36),"") -> -0.012298282 | AM36: =IFERROR((AB36*$AH$36),"") -> -0.014640812 | AN36: =IFERROR((AC36*$AH$36),"") -> -0.0076132223 | AO36: =IFERROR(AD36*AH36,"") -> -0.011517439 | AP36: =IFERROR(STDEV(AI36:AN36), "") -> 0.0032005052
D37: F | E37: =Data!B32 -> 1.838 | F37: =Data!C32 -> 1.883 | G37: =Data!D32 -> 1.844 | H37: =Data!E32 -> 1.838 | I37: =Data!F32 -> 1.883 | J37: =Data!G32 -> 1.844 | M37: F | N37: =IF(((E37-$P$11)/$P$10)>0,((E37-$P$11)/$P$10)," ") -> 1.6016398 | O37: =IF(((F37-$P$11)/$P$10)>0,((F37-$P$11)/$P$10)," ") -> 1.6455622 | P37: =IF(((G37-$P$11)/$P$10)>0,((G37-$P$11)/$P$10)," ") -> 1.6074961 | Q37: =IF(((H37-$P$11)/$P$10)>0,((H37-$P$11)/$P$10)," ") -> 1.6016398 | R37: =IF(((I37-$P$11)/$P$10)>0,((I37-$P$11)/$P$10)," ") -> 1.6455622 | S37: =IF(((J37-$P$11)/$P$10)>0,((J37-$P$11)/$P$10)," ") -> 1.6074961 | T37: =IFERROR(AVERAGE(N37:S37),"") -> 1.6182327 | U37: =IFERROR(STDEV(N37:S37),"") -> 0.021330747 | W37: 5 | X37: =IFERROR(($N$19-N37)/W37,"") -> 0.011517439 | Y37: =IFERROR(($O$19-O37)/W37,"") -> 0.0099557522 | Z37: =IFERROR(($P$19-P37)/W37,"") -> 0.0099557522 | AA37: =IFERROR(($Q$19-Q37)/W37,"") -> 0.011517439 | AB37: =IFERROR(($R$19-R37)/W37,"") -> 0.0099557522 | AC37: =IFERROR(($S$19-S37)/W37,"") -> 0.0099557522 | AD37: =IFERROR(AVERAGE(X37:AC37), "") -> 0.010476314 | AE37: =IFERROR(STDEV(X37:AC37), "") -> 0.0008064515 | AH37: ='Sample ID'!$F$11 -> 0 | AI37: =IFERROR((X37*$AH$37),"") -> 0 | AJ37: =IFERROR((Y37*$AH$37),"") -> 0 | AK37: =IFERROR((Z37*$AH$37),"") -> 0 | AL37: =IFERROR((AA37*$AH$37),"") -> 0 | AM37: =IFERROR((AB37*$AH$37),"") -> 0 | AN37: =IFERROR((AC37*$AH$37),"") -> 0 | AO37: =IFERROR(AD37*AH37,"") -> 0 | AP37: =IFERROR(STDEV(AI37:AN37), "") -> 0
D38: G | E38: =Data!B33 -> 1.871 | F38: =Data!C33 -> 1.88 | G38: =Data!D33 -> 1.89 | H38: =Data!E33 -> 1.871 | I38: =Data!F33 -> 1.88 | J38: =Data!G33 -> 1.89 | M38: G | N38: =IF(((E38-$P$11)/$P$10)>0,((E38-$P$11)/$P$10)," ") -> 1.6338496 | O38: =IF(((F38-$P$11)/$P$10)>0,((F38-$P$11)/$P$10)," ") -> 1.642634 | P38: =IF(((G38-$P$11)/$P$10)>0,((G38-$P$11)/$P$10)," ") -> 1.6523946 | Q38: =IF(((H38-$P$11)/$P$10)>0,((H38-$P$11)/$P$10)," ") -> 1.6338496 | R38: =IF(((I38-$P$11)/$P$10)>0,((I38-$P$11)/$P$10)," ") -> 1.642634 | S38: =IF(((J38-$P$11)/$P$10)>0,((J38-$P$11)/$P$10)," ") -> 1.6523946 | T38: =IFERROR(AVERAGE(N38:S38),"") -> 1.6429594 | U38: =IFERROR(STDEV(N38:S38),"") -> 0.008297417 | W38: 5 | X38: =IFERROR(($N$20-N38)/W38,"") -> 0.0070275898 | Y38: =IFERROR(($O$20-O38)/W38,"") -> 0.0042946382 | Z38: =IFERROR(($P$20-P38)/W38,"") -> 0.0046850599 | AA38: =IFERROR(($Q$20-Q38)/W38,"") -> 0.0070275898 | AB38: =IFERROR(($R$20-R38)/W38,"") -> 0.0042946382 | AC38: =IFERROR(($S$20-S38)/W38,"") -> 0.0046850599 | AD38: =IFERROR(AVERAGE(X38:AC38), "") -> 0.0053357626 | AE38: =IFERROR(STDEV(X38:AC38), "") -> 0.001322064 | AH38: ='Sample ID'!$F$12 -> 0 | AI38: =IFERROR((X38*$AH$38),"") -> 0 | AJ38: =IFERROR((Y38*$AH$38),"") -> 0 | AK38: =IFERROR((Z38*$AH$38),"") -> 0 | AL38: =IFERROR((AA38*$AH$38),"") -> 0 | AM38: =IFERROR((AB38*$AH$38),"") -> 0 | AN38: =IFERROR((AC38*$AH$38),"") -> 0 | AO38: =IFERROR(AD38*AH38,"") -> 0 | AP38: =IFERROR(STDEV(AI38:AN38), "") -> 0
D39: H | E39: =Data!B34 -> 0 | F39: =Data!C34 -> 0 | G39: =Data!D34 -> 0 | H39: =Data!E34 -> 0 | I39: =Data!F34 -> 0 | J39: =Data!G34 -> 0 | M39: H | N39: =IF(((E39-$P$11)/$P$10)>0,((E39-$P$11)/$P$10)," ") | O39: =IF(((F39-$P$11)/$P$10)>0,((F39-$P$11)/$P$10)," ") | P39: =IF(((G39-$P$11)/$P$10)>0,((G39-$P$11)/$P$10)," ") | Q39: =IF(((H39-$P$11)/$P$10)>0,((H39-$P$11)/$P$10)," ") | R39: =IF(((I39-$P$11)/$P$10)>0,((I39-$P$11)/$P$10)," ") | S39: =IF(((J39-$P$11)/$P$10)>0,((J39-$P$11)/$P$10)," ") | T39: =IFERROR(AVERAGE(N39:S39),"") | U39: =IFERROR(STDEV(N39:S39),"") | W39: 5 | X39: =IFERROR(($N$21-N39)/W39,"") | Y39: =IFERROR(($O$21-O39)/W39,"") | Z39: =IFERROR(($P$21-P39)/W39,"") | AA39: =IFERROR(($Q$21-Q39)/W39,"") | AB39: =IFERROR(($R$21-R39)/W39,"") | AC39: =IFERROR(($S$21-S39)/W39,"") | AD39: =IFERROR(AVERAGE(X39:AC39), "") | AE39: =IFERROR(STDEV(X39:AC39), "") | AH39: ='Sample ID'!$F$13 -> 0 | AI39: =IFERROR((X39*$AH$39),"") | AJ39: =IFERROR((Y39*$AH$39),"") | AK39: =IFERROR((Z39*$AH$39),"") | AL39: =IFERROR((AA39*$AH$39),"") | AM39: =IFERROR((AB39*$AH$39),"") | AN39: =IFERROR((AC39*$AH$39),"") | AO39: =IFERROR(AD39*AH39,"") | AP39: =IFERROR(STDEV(AI39:AN39), "")
E40: 7 | F40: 8 | G40: 9 | H40: 10 | I40: 11 | J40: 12 | N40: 7 | O40: 8 | P40: 9 | Q40: 10 | R40: 11 | S40: 12 | T40: Average SC (mg/ml) | U40: Std Dev | X40: 7 | Y40: 8 | Z40: 9 | AA40: 10 | AB40: 11 | AC40: 12 | AD40: Average Δ SC (mg/ml/min) | AE40: Std Dev | AP40: Std Dev
D41: A | E41: =Data!H27 -> 0 | F41: =Data!I27 -> 0 | G41: =Data!J27 -> 0 | H41: =Data!K27 -> 0 | I41: =Data!L27 -> 0 | J41: =Data!M27 -> 0 | M41: A | N41: =IF(((E41-$P$11)/$P$10)>0,((E41-$P$11)/$P$10)," ") | O41: =IF(((F41-$P$11)/$P$10)>0,((F41-$P$11)/$P$10)," ") | P41: =IF(((G41-$P$11)/$P$10)>0,((G41-$P$11)/$P$10)," ") | Q41: =IF(((H41-$P$11)/$P$10)>0,((H41-$P$11)/$P$10)," ") | R41: =IF(((I41-$P$11)/$P$10)>0,((I41-$P$11)/$P$10)," ") | S41: =IF(((J41-$P$11)/$P$10)>0,((J41-$P$11)/$P$10)," ") | T41: =IFERROR(AVERAGE(N41:S41),"") | U41: =IFERROR(STDEV(N41:S41),"") | W41: 5 | X41: =IFERROR(($N$23-N41)/W41,"") | Y41: =IFERROR(($O$23-O41)/W41,"") | Z41: =IFERROR(($P$23-P41)/W41,"") | AA41: =IFERROR(($Q$23-Q41)/W41,"") | AB41: =IFERROR(($R$23-R41)/W41,"") | AC41: =IFERROR(($S$23-S41)/W41,"") | AD41: =IFERROR(AVERAGE(X41:AC41), "") | AE41: =IFERROR(STDEV(X41:AC41), "") | AH41: ='Sample ID'!$F$14 -> 0 | AI41: =IFERROR((X41*$AH$41),"") | AJ41: =IFERROR((Y41*$AH$41),"") | AK41: =IFERROR((Z41*$AH$41),"") | AL41: =IFERROR((AA41*$AH$41),"") | AM41: =IFERROR((AB41*$AH$41),"") | AN41: =IFERROR((AC41*$AH$41),"") | AO41: =IFERROR(AD41*AH41,"") | AP41: =IFERROR(STDEV(AI41:AN41), "")
D42: B | E42: =Data!H28 -> 0 | F42: =Data!I28 -> 0 | G42: =Data!J28 -> 0 | H42: =Data!K28 -> 0 | I42: =Data!L28 -> 0 | J42: =Data!M28 -> 0 | M42: B | N42: =IF(((E42-$P$11)/$P$10)>0,((E42-$P$11)/$P$10)," ") | O42: =IF(((F42-$P$11)/$P$10)>0,((F42-$P$11)/$P$10)," ") | P42: =IF(((G42-$P$11)/$P$10)>0,((G42-$P$11)/$P$10)," ") | Q42: =IF(((H42-$P$11)/$P$10)>0,((H42-$P$11)/$P$10)," ") | R42: =IF(((I42-$P$11)/$P$10)>0,((I42-$P$11)/$P$10)," ") | S42: =IF(((J42-$P$11)/$P$10)>0,((J42-$P$11)/$P$10)," ") | T42: =IFERROR(AVERAGE(N42:S42),"") | U42: =IFERROR(STDEV(N42:S42),"") | W42: 5 | X42: =IFERROR(($N$24-N42)/W42,"") | Y42: =IFERROR(($O$24-O42)/W42,"") | Z42: =IFERROR(($P$24-P42)/W42,"") | AA42: =IFERROR(($Q$24-Q42)/W42,"") | AB42: =IFERROR(($R$24-R42)/W42,"") | AC42: =IFERROR(($S$24-S42)/W42,"") | AD42: =IFERROR(AVERAGE(X42:AC42), "") | AE42: =IFERROR(STDEV(X42:AC42), "") | AH42: ='Sample ID'!$F$15 -> 0 | AI42: =IFERROR((X42*$AH$42),"") | AJ42: =IFERROR((Y42*$AH$42),"") | AK42: =IFERROR((Z42*$AH$42),"") | AL42: =IFERROR((AA42*$AH$42),"") | AM42: =IFERROR((AB42*$AH$42),"") | AN42: =IFERROR((AC42*$AH$42),"") | AO42: =IFERROR(AD42*AH42,"") | AP42: =IFERROR(STDEV(AI42:AN42), "")
D43: C | E43: =Data!H29 -> 0 | F43: =Data!I29 -> 0 | G43: =Data!J29 -> 0 | H43: =Data!K29 -> 0 | I43: =Data!L29 -> 0 | J43: =Data!M29 -> 0 | M43: C | N43: =IF(((E43-$P$11)/$P$10)>0,((E43-$P$11)/$P$10)," ") | O43: =IF(((F43-$P$11)/$P$10)>0,((F43-$P$11)/$P$10)," ") | P43: =IF(((G43-$P$11)/$P$10)>0,((G43-$P$11)/$P$10)," ") | Q43: =IF(((H43-$P$11)/$P$10)>0,((H43-$P$11)/$P$10)," ") | R43: =IF(((I43-$P$11)/$P$10)>0,((I43-$P$11)/$P$10)," ") | S43: =IF(((J43-$P$11)/$P$10)>0,((J43-$P$11)/$P$10)," ") | T43: =IFERROR(AVERAGE(N43:S43),"") | U43: =IFERROR(STDEV(N43:S43),"") | W43: 5 | X43: =IFERROR(($N$25-N43)/W43,"") | Y43: =IFERROR(($O$25-O43)/W43,"") | Z43: =IFERROR(($P$25-P43)/W43,"") | AA43: =IFERROR(($Q$25-Q43)/W43,"") | AB43: =IFERROR(($R$25-R43)/W43,"") | AC43: =IFERROR(($S$25-S43)/W43,"") | AD43: =IFERROR(AVERAGE(X43:AC43), "") | AE43: =IFERROR(STDEV(X43:AC43), "") | AH43: ='Sample ID'!$F$16 -> 0 | AI43: =IFERROR((X43*$AH$43),"") | AJ43: =IFERROR((Y43*$AH$43),"") | AK43: =IFERROR((Z43*$AH$43),"") | AL43: =IFERROR((AA43*$AH$43),"") | AM43: =IFERROR((AB43*$AH$43),"") | AN43: =IFERROR((AC43*$AH$43),"") | AO43: =IFERROR(AD43*AH43,"") | AP43: =IFERROR(STDEV(AI43:AN43), "")
D44: D | E44: =Data!H30 -> 0 | F44: =Data!I30 -> 0 | G44: =Data!J30 -> 0 | H44: =Data!K30 -> 0 | I44: =Data!L30 -> 0 | J44: =Data!M30 -> 0 | M44: D | N44: =IF(((E44-$P$11)/$P$10)>0,((E44-$P$11)/$P$10)," ") | O44: =IF(((F44-$P$11)/$P$10)>0,((F44-$P$11)/$P$10)," ") | P44: =IF(((G44-$P$11)/$P$10)>0,((G44-$P$11)/$P$10)," ") | Q44: =IF(((H44-$P$11)/$P$10)>0,((H44-$P$11)/$P$10)," ") | R44: =IF(((I44-$P$11)/$P$10)>0,((I44-$P$11)/$P$10)," ") | S44: =IF(((J44-$P$11)/$P$10)>0,((J44-$P$11)/$P$10)," ") | T44: =IFERROR(AVERAGE(N44:S44),"") | U44: =IFERROR(STDEV(N44:S44),"") | W44: 5 | X44: =IFERROR(($N$26-N44)/W44,"") | Y44: =IFERROR(($O$26-O44)/W44,"") | Z44: =IFERROR(($P$26-P44)/W44,"") | AA44: =IFERROR(($Q$17-Q44)/W44,"") | AB44: =IFERROR(($R$26-R44)/W44,"") | AC44: =IFERROR(($S$26-S44)/W44,"") | AD44: =IFERROR(AVERAGE(X44:AC44), "") | AE44: =IFERROR(STDEV(X44:AC44), "") | AH44: ='Sample ID'!$F$17 -> 0 | AI44: =IFERROR((X44*$AH$44),"") | AJ44: =IFERROR((Y44*$AH$44),"") | AK44: =IFERROR((Z44*$AH$44),"") | AL44: =IFERROR((AA44*$AH$44),"") | AM44: =IFERROR((AB44*$AH$44),"") | AN44: =IFERROR((AC44*$AH$44),"") | AO44: =IFERROR(AD44*AH44,"") | AP44: =IFERROR(STDEV(AI44:AN44), "")
D45: E | E45: =Data!H31 -> 0 | F45: =Data!I31 -> 0 | G45: =Data!J31 -> 0 | H45: =Data!K31 -> 0 | I45: =Data!L31 -> 0 | J45: =Data!M31 -> 0 | M45: E | N45: =IF(((E45-$P$11)/$P$10)>0,((E45-$P$11)/$P$10)," ") | O45: =IF(((F45-$P$11)/$P$10)>0,((F45-$P$11)/$P$10)," ") | P45: =IF(((G45-$P$11)/$P$10)>0,((G45-$P$11)/$P$10)," ") | Q45: =IF(((H45-$P$11)/$P$10)>0,((H45-$P$11)/$P$10)," ") | R45: =IF(((I45-$P$11)/$P$10)>0,((I45-$P$11)/$P$10)," ") | S45: =IF(((J45-$P$11)/$P$10)>0,((J45-$P$11)/$P$10)," ") | T45: =IFERROR(AVERAGE(N45:S45),"") | U45: =IFERROR(STDEV(N45:S45),"") | W45: 5 | X45: =IFERROR(($N$27-N45)/W45,"") | Y45: =IFERROR(($O$27-O45)/W45,"") | Z45: =IFERROR(($P$27-P45)/W45,"") | AA45: =IFERROR(($Q$18-Q45)/W45,"") | AB45: =IFERROR(($R$27-R45)/W45,"") | AC45: =IFERROR(($S$27-S45)/W45,"") | AD45: =IFERROR(AVERAGE(X45:AC45), "") | AE45: =IFERROR(STDEV(X45:AC45), "") | AH45: ='Sample ID'!$F$18 -> 0 | AI45: =IFERROR((X45*$AH$45),"") | AJ45: =IFERROR((Y45*$AH$45),"") | AK45: =IFERROR((Z45*$AH$45),"") | AL45: =IFERROR((AA45*$AH$45),"") | AM45: =IFERROR((AB45*$AH$45),"") | AN45: =IFERROR((AC45*$AH$45),"") | AO45: =IFERROR(AD45*AH45,"") | AP45: =IFERROR(STDEV(AI45:AN45), "")
D46: F | E46: =Data!H32 -> 0 | F46: =Data!I32 -> 0 | G46: =Data!J32 -> 0 | H46: =Data!K32 -> 0 | I46: =Data!L32 -> 0 | J46: =Data!M32 -> 0 | M46: F | N46: =IF(((E46-$P$11)/$P$10)>0,((E46-$P$11)/$P$10)," ") | O46: =IF(((F46-$P$11)/$P$10)>0,((F46-$P$11)/$P$10)," ") | P46: =IF(((G46-$P$11)/$P$10)>0,((G46-$P$11)/$P$10)," ") | Q46: =IF(((H46-$P$11)/$P$10)>0,((H46-$P$11)/$P$10)," ") | R46: =IF(((I46-$P$11)/$P$10)>0,((I46-$P$11)/$P$10)," ") | S46: =IF(((J46-$P$11)/$P$10)>0,((J46-$P$11)/$P$10)," ") | T46: =IFERROR(AVERAGE(N46:S46),"") | U46: =IFERROR(STDEV(N46:S46),"") | W46: 5 | X46: =IFERROR(($N$28-N46)/W46,"") | Y46: =IFERROR(($O$28-O46)/W46,"") | Z46: =IFERROR(($P$28-P46)/W46,"") | AA46: =IFERROR(($Q$19-Q46)/W46,"") | AB46: =IFERROR(($R$28-R46)/W46,"") | AC46: =IFERROR(($S$28-S46)/W46,"") | AD46: =IFERROR(AVERAGE(X46:AC46), "") | AE46: =IFERROR(STDEV(X46:AC46), "") | AH46: ='Sample ID'!$F$19 -> 0 | AI46: =IFERROR((X46*$AH$46),"") | AJ46: =IFERROR((Y46*$AH$46),"") | AK46: =IFERROR((Z46*$AH$46),"") | AL46: =IFERROR((AA46*$AH$46),"") | AM46: =IFERROR((AB46*$AH$46),"") | AN46: =IFERROR((AC46*$AH$46),"") | AO46: =IFERROR(AD46*AH46,"") | AP46: =IFERROR(STDEV(AI46:AN46), "")
D47: G | E47: =Data!H33 -> 0 | F47: =Data!I33 -> 0 | G47: =Data!J33 -> 0 | H47: =Data!K33 -> 0 | I47: =Data!L33 -> 0 | J47: =Data!M33 -> 0 | M47: G | N47: =IF(((E47-$P$11)/$P$10)>0,((E47-$P$11)/$P$10)," ") | O47: =IF(((F47-$P$11)/$P$10)>0,((F47-$P$11)/$P$10)," ") | P47: =IF(((G47-$P$11)/$P$10)>0,((G47-$P$11)/$P$10)," ") | Q47: =IF(((H47-$P$11)/$P$10)>0,((H47-$P$11)/$P$10)," ") | R47: =IF(((I47-$P$11)/$P$10)>0,((I47-$P$11)/$P$10)," ") | S47: =IF(((J47-$P$11)/$P$10)>0,((J47-$P$11)/$P$10)," ") | T47: =IFERROR(AVERAGE(N47:S47),"") | U47: =IFERROR(STDEV(N47:S47),"") | W47: 5 | X47: =IFERROR(($N$29-N47)/W47,"") | Y47: =IFERROR(($O$29-O47)/W47,"") | Z47: =IFERROR(($P$29-P47)/W47,"") | AA47: =IFERROR(($Q$20-Q47)/W47,"") | AB47: =IFERROR(($R$29-R47)/W47,"") | AC47: =IFERROR(($S$29-S47)/W47,"") | AD47: =IFERROR(AVERAGE(X47:AC47), "") | AE47: =IFERROR(STDEV(X47:AC47), "") | AH47: ='Sample ID'!$F$20 -> 0 | AI47: =IFERROR((X47*$AH$47),"") | AJ47: =IFERROR((Y47*$AH$47),"") | AK47: =IFERROR((Z47*$AH$47),"") | AL47: =IFERROR((AA47*$AH$47),"") | AM47: =IFERROR((AB47*$AH$47),"") | AN47: =IFERROR((AC47*$AH$47),"") | AO47: =IFERROR(AD47*AH47,"") | AP47: =IFERROR(STDEV(AI47:AN47), "")
D48: H | E48: =Data!H34 -> 0 | F48: =Data!I34 -> 0 | G48: =Data!J34 -> 0 | H48: =Data!K34 -> 0 | I48: =Data!L34 -> 0 | J48: =Data!M34 -> 0 | M48: H | N48: =IF(((E48-$P$11)/$P$10)>0,((E48-$P$11)/$P$10)," ") | O48: =IF(((F48-$P$11)/$P$10)>0,((F48-$P$11)/$P$10)," ") | P48: =IF(((G48-$P$11)/$P$10)>0,((G48-$P$11)/$P$10)," ") | Q48: =IF(((H48-$P$11)/$P$10)>0,((H48-$P$11)/$P$10)," ") | R48: =IF(((I48-$P$11)/$P$10)>0,((I48-$P$11)/$P$10)," ") | S48: =IF(((J48-$P$11)/$P$10)>0,((J48-$P$11)/$P$10)," ") | T48: =IFERROR(AVERAGE(N48:S48),"") | U48: =IFERROR(STDEV(N48:S48),"") | W48: 5 | X48: =IFERROR(($N$30-N48)/W48,"") | Y48: =IFERROR(($O$30-O48)/W48,"") | Z48: =IFERROR(($P$30-P48)/W48,"") | AA48: =IFERROR(($Q$21-Q48)/W48,"") | AB48: =IFERROR(($R$30-R48)/W48,"") | AC48: =IFERROR(($S$30-S48)/W48,"") | AD48: =IFERROR(AVERAGE(X48:AC48), "") | AE48: =IFERROR(STDEV(X48:AC48), "") | AH48: ='Sample ID'!$F$21 -> 0 | AI48: =IFERROR((X48*$AH$48),"") | AJ48: =IFERROR((Y48*$AH$48),"") | AK48: =IFERROR((Z48*$AH$48),"") | AL48: =IFERROR((AA48*$AH$48),"") | AM48: =IFERROR((AB48*$AH$48),"") | AN48: =IFERROR((AC48*$AH$48),"") | AO48: =IFERROR(AD48*AH48,"") | AP48: =IFERROR(STDEV(AI48:AN48), "")
...

Sheet Std Curve
B2: Standard Curve Calibration
B6: Substrate Conc. (mg/ml) | C6: OD | D6: OD | E6: OD | F6: Avg | G6: Std Dev | H6: Description
B7: 0.25 | C7: 0.436 | D7: 0.409 | E7: 0.411 | F7: =AVERAGE(C7:E7) -> 0.41866667 | G7: =STDEV(C7:E7) -> 0.015044379 | H7: This data is generated by taking a substrate with known concentration of plastic and measuring the optical density in triplicate per concentration. This generates a standard curve which can be used to determine the weight of plastic broken down in future readings
B8: 0.5 | C8: 0.718 | D8: 0.726 | E8: 0.696 | F8: =AVERAGE(C8:E8) -> 0.71333333 | G8: =STDEV(C8:E8) -> 0.015534907
B9: 1 | C9: 1.198 | D9: 1.211 | E9: 1.152 | F9: =AVERAGE(C9:E9) -> 1.187 | G9: =STDEV(C9:E9) -> 0.031
B10: 1.25 | C10: 1.476 | D10: 1.53 | E10: 1.484 | F10: =AVERAGE(C10:E10) -> 1.4966667 | G10: =STDEV(C10:E10) -> 0.029143324
B11: 1.5 | C11: 1.736 | D11: 1.795 | E11: 1.757 | F11: =AVERAGE(C11:E11) -> 1.7626667 | G11: =STDEV(C11:E11) -> 0.029905406
B12: 2 | C12: 2.189 | D12: 2.241 | E12: 2.257 | F12: =AVERAGE(C12:E12) -> 2.229 | G12: =STDEV(C12:E12) -> 0.035552778
B14: Slope & y-intercept
B17: Description | C17: Variable | D17: Value
B18: Plastic Type (manual input): | C18: PCL | D18: -
B19: Gradient of std curve | C19: m | D19: =SLOPE(F8:F12,B8:B12) -> 1.0245333
B20: Y-axis Intercept | C20: c | D20: =INTERCEPT(F8:F12,B8:B12) -> 0.19706667
B21: Fit of Line (must be >= 0,98 | C21: R^2 | D21: =RSQ(F8:F12,B8:B12) -> 0.99795052
B23: Do not modify the slope or intercept values. These are calculated from the standard curve data and automatically integrated into the results sheet to compute the concentration of the substrate.

Sheet Substrate Degradation (mg ml)
B3: Substrate Degradation (mg/ml)
B5: No | C5: Sample ID | D5: Diluton Factor | E5: Graph Label | F5: 0 | G5: 5 | H5: 10 | I5: 15 | J5: 20 | K5: 25 | L5: 30 | M5: 35 | N5: 40 | O5: 45 | P5: 50 | Q5: 55 | R5: 60 | S5: 65 | T5: 70 | U5: 75 | V5: 80 | W5: 85 | X5: 90
B6: ='Sample ID'!D6 -> A 1-6 | C6: ='Sample ID'!E6 -> 484 | D6: ='Sample ID'!F6 -> 1 | E6: =C6 & " - DF " & D6 -> 484 - DF 1 | F6: =Results!T14 -> 1.7402395 | G6: =Results!T32 -> 1.7242972 | H6: =Results!T50 -> 1.7288522 | I6: =Results!T68 -> 1.7242972 | J6: =Results!T86 -> 1.7093311 | K6: =Results!T104 -> 1.7015226 | L6: =Results!T122 -> 1.696317 | M6: =Results!T140 -> 1.6904607 | N6: =Results!T158 -> 1.696317 | O6: =Results!T176 -> 1.6924128 | P6: =Results!T194 -> 1.68981 | Q6: =Results!T212 -> 1.6816762 | R6: =Results!T230 -> 1.6826523 | S6: =Results!T248 -> 1.6793988 | T6: =Results!T266 -> 1.6780973 | U6: =Results!T284 | V6: =Results!T302 | W6: =Results!T320 | X6: =Results!T338
B7: ='Sample ID'!D7 -> B 1-6 | C7: ='Sample ID'!E7 -> 548 | D7: ='Sample ID'!F7 -> 1 | E7: =C7 & " - DF " & D7 -> 548 - DF 1 | F7: =Results!T15 -> 1.7255986 | G7: =Results!T33 -> 1.7415409 | H7: =Results!T51 -> 1.7561817 | I7: =Results!T69 -> 1.7587845 | J7: =Results!T87 -> 1.7542296 | K7: =Results!T105 -> 1.75 | L7: =Results!T123 -> 1.7561817 | M7: =Results!T141 -> 1.7665929 | N7: =Results!T159 -> 1.7711478 | O7: =Results!T177 -> 1.7838365 | P7: =Results!T195 -> 1.7815591 | Q7: =Results!T213 -> 1.7763535 | R7: =Results!T231 -> 1.7792816 | S7: =Results!T249 -> 1.7773295 | T7: =Results!T267 -> 1.7773295 | U7: =Results!T285 | V7: =Results!T303 | W7: =Results!T321 | X7: =Results!T339
B8: ='Sample ID'!D8 -> C1-6 | C8: ='Sample ID'!E8 -> 716 | D8: ='Sample ID'!F8 -> 1 | E8: =C8 & " - DF " & D8 -> 716 - DF 1 | F8: =Results!T16 -> 1.7617126 | G8: =Results!T34 -> 1.7626887 | H8: =Results!T52 -> 1.7747267 | I8: =Results!T70 -> 1.7779802 | J8: =Results!T88 -> 1.7763535 | K8: =Results!T106 -> 1.7747267 | L8: =Results!T124 -> 1.7734253 | M8: =Results!T142 -> 1.7662676 | N8: =Results!T160 -> 1.7597605 | O8: =Results!T178 -> 1.7591098 | P8: =Results!T196 -> 1.7535789 | Q8: =Results!T214 -> 1.75 | R8: =Results!T232 -> 1.7581338 | S8: =Results!T250 -> 1.7584591 | T8: =Results!T268 -> 1.7688704 | U8: =Results!T286 | V8: =Results!T304 | W8: =Results!T322 | X8: =Results!T340
B9: ='Sample ID'!D9 -> D 1-6 | C9: ='Sample ID'!E9 -> 824 | D9: ='Sample ID'!F9 -> 1 | E9: =C9 & " - DF " & D9 -> 824 - DF 1 | F9: =Results!T17 -> 1.809214 | G9: =Results!T35 -> 1.9100729 | H9: =Results!T53 -> 1.961153 | I9: =Results!T71 -> 1.9943389 | J9: =Results!T89 -> 1.9969417 | K9: =Results!T107 -> 1.996291 | L9: =Results!T125 -> 1.9992192 | M9: =Results!T143 -> 2.0164628 | N9: =Results!T161 -> 2.0164628 | O9: =Results!T179 -> 2.0210177 | P9: =Results!T197 -> 2.0229698 | Q9: =Results!T215 -> 2.0216684 | R9: =Results!T233 -> 2.0232952 | S9: =Results!T251 -> 2.0210177 | T9: =Results!T269 -> 2.0249219 | U9: =Results!T287 | V9: =Results!T305 | W9: =Results!T323 | X9: =Results!T341
B10: ='Sample ID'!D10 -> E 1-6 | C10: ='Sample ID'!E10 -> 437 | D10: ='Sample ID'!F10 -> 1 | E10: =C10 & " - DF " & D10 -> 437 - DF 1 | F10: =Results!T18 -> 1.8401223 | G10: =Results!T36 -> 1.8977095 | H10: =Results!T54 -> 1.9221109 | I10: =Results!T72 -> 1.9396799 | J10: =Results!T90 -> 1.9341489 | K10: =Results!T108 -> 1.9374024 | L10: =Results!T126 -> 1.9338235 | M10: =Results!T144 -> 1.941632 | N10: =Results!T162 -> 1.9400052 | O10: =Results!T180 -> 1.9377277 | P10: =Results!T198 -> 1.9243883 | Q10: =Results!T216 -> 1.9286179 | R10: =Results!T234 -> 1.9208095 | S10: =Results!T252 -> 1.9221109 | T10: =Results!T270 -> 1.9276419 | U10: =Results!T288 | V10: =Results!T306 | W10: =Results!T324 | X10: =Results!T342
B11: ='Sample ID'!D11 -> F 1-6 | C11: ='Sample ID'!E11 -> 0 | D11: ='Sample ID'!F11 -> 0 | E11: =C11 & " - DF " & D11 -> 0 - DF 0 | F11: =Results!T19 -> 1.6706143 | G11: =Results!T37 -> 1.6182327 | H11: =Results!T55 -> 1.5577173 | I11: =Results!T73 -> 1.4932978 | J11: =Results!T91 -> 1.4266007 | K11: =Results!T109 -> 1.3690135 | L11: =Results!T127 -> 1.3034552 | M11: =Results!T145 -> 1.2577434 | N11: =Results!T163 -> 1.203735 | O11: =Results!T181 -> 1.1513535 | P11: =Results!T199 -> 1.0973451 | Q11: =Results!T217 -> 1.0508199 | R11: =Results!T235 -> 0.99323269 | S11: =Results!T253 -> 0.92328214 | T11: =Results!T271 -> 0.85072879 | U11: =Results!T289 | V11: =Results!T307 | W11: =Results!T325 | X11: =Results!T343
B12: ='Sample ID'!D12 -> G 1-6 | C12: ='Sample ID'!E12 -> 0 | D12: ='Sample ID'!F12 -> 0 | E12: =C12 & " - DF " & D12 -> 0 - DF 0 | F12: =Results!T20 -> 1.6696382 | G12: =Results!T38 -> 1.6429594 | H12: =Results!T56 -> 1.6224623 | I12: =Results!T74 -> 1.5899271 | J12: =Results!T92 -> 1.5534878 | K12: =Results!T110 -> 1.5264836 | L12: =Results!T128 -> 1.5007808 | M12: =Results!T146 -> 1.4923217 | N12: =Results!T164 -> 1.4838626 | O12: =Results!T182 -> 1.4747527 | P12: =Results!T200 -> 1.4636908 | Q12: =Results!T218 -> 1.4539302 | R12: =Results!T236 -> 1.4337585 | S12: =Results!T254 -> 1.4051275 | T12: =Results!T272 -> 1.3716163 | U12: =Results!T290 | V12: =Results!T308 | W12: =Results!T326 | X12: =Results!T344
B13: ='Sample ID'!D13 -> H 1-6 | C13: ='Sample ID'!E13 -> 0 | D13: ='Sample ID'!F13 -> 0 | E13: =C13 & " - DF " & D13 -> 0 - DF 0 | F13: =Results!T21 | G13: =Results!T39 | H13: =Results!T57 | I13: =Results!T75 | J13: =Results!T93 | K13: =Results!T111 | L13: =Results!T129 | M13: =Results!T147 | N13: =Results!T165 | O13: =Results!T183 | P13: =Results!T201 | Q13: =Results!T219 | R13: =Results!T237 | S13: =Results!T255 | T13: =Results!T273 | U13: =Results!T291 | V13: =Results!T309 | W13: =Results!T327 | X13: =Results!T345
B14: ='Sample ID'!D14 -> A 7-12 | C14: ='Sample ID'!E14 -> 0 | D14: ='Sample ID'!F14 -> 0 | E14: =C14 & " - DF " & D14 -> 0 - DF 0 | F14: =Results!T23 | G14: =Results!T41 | H14: =Results!T59 | I14: =Results!T77 | J14: =Results!T95 | K14: =Results!T113 | L14: =Results!T131 | M14: =Results!T149 | N14: =Results!T167 | O14: =Results!T185 | P14: =Results!T203 | Q14: =Results!T221 | R14: =Results!T239 | S14: =Results!T257 | T14: =Results!T275 | U14: =Results!T293 | V14: =Results!T311 | W14: =Results!T329 | X14: =Results!T347
B15: ='Sample ID'!D15 -> B 7-12 | C15: ='Sample ID'!E15 -> 0 | D15: ='Sample ID'!F15 -> 0 | E15: =C15 & " - DF " & D15 -> 0 - DF 0 | F15: =Results!T24 | G15: =Results!T42 | H15: =Results!T60 | I15: =Results!T78 | J15: =Results!T96 | K15: =Results!T114 | L15: =Results!T132 | M15: =Results!T150 | N15: =Results!T168 | O15: =Results!T186 | P15: =Results!T204 | Q15: =Results!T222 | R15: =Results!T240 | S15: =Results!T258 | T15: =Results!T276 | U15: =Results!T294 | V15: =Results!T312 | W15: =Results!T330 | X15: =Results!T348
B16: ='Sample ID'!D16 -> C7-12 | C16: ='Sample ID'!E16 -> 0 | D16: ='Sample ID'!F16 -> 0 | E16: =C16 & " - DF " & D16 -> 0 - DF 0 | F16: =Results!T25 | G16: =Results!T43 | H16: =Results!T61 | I16: =Results!T79 | J16: =Results!T97 | K16: =Results!T115 | L16: =Results!T133 | M16: =Results!T151 | N16: =Results!T169 | O16: =Results!T187 | P16: =Results!T205 | Q16: =Results!T223 | R16: =Results!T241 | S16: =Results!T259 | T16: =Results!T277 | U16: =Results!T295 | V16: =Results!T313 | W16: =Results!T331 | X16: =Results!T349
B17: ='Sample ID'!D17 -> D 7-12 | C17: ='Sample ID'!E17 -> 0 | D17: ='Sample ID'!F17 -> 0 | E17: =C17 & " - DF " & D17 -> 0 - DF 0 | F17: =Results!T26 | G17: =Results!T44 | H17: =Results!T62 | I17: =Results!T80 | J17: =Results!T98 | K17: =Results!T116 | L17: =Results!T134 | M17: =Results!T152 | N17: =Results!T170 | O17: =Results!T188 | P17: =Results!T206 | Q17: =Results!T224 | R17: =Results!T242 | S17: =Results!T260 | T17: =Results!T278 | U17: =Results!T296 | V17: =Results!T314 | W17: =Results!T332 | X17: =Results!T350
B18: ='Sample ID'!D18 -> E 7-12 | C18: ='Sample ID'!E18 -> 0 | D18: ='Sample ID'!F18 -> 0 | E18: =C18 & " - DF " & D18 -> 0 - DF 0 | F18: =Results!T27 | G18: =Results!T45 | H18: =Results!T63 | I18: =Results!T81 | J18: =Results!T99 | K18: =Results!T117 | L18: =Results!T135 | M18: =Results!T153 | N18: =Results!T171 | O18: =Results!T189 | P18: =Results!T207 | Q18: =Results!T225 | R18: =Results!T243 | S18: =Results!T261 | T18: =Results!T279 | U18: =Results!T297 | V18: =Results!T315 | W18: =Results!T333 | X18: =Results!T351
B19: ='Sample ID'!D19 -> F 7-12 | C19: ='Sample ID'!E19 -> 0 | D19: ='Sample ID'!F19 -> 0 | E19: =C19 & " - DF " & D19 -> 0 - DF 0 | F19: =Results!T28 | G19: =Results!T46 | H19: =Results!T64 | I19: =Results!T82 | J19: =Results!T100 | K19: =Results!T118 | L19: =Results!T136 | M19: =Results!T154 | N19: =Results!T172 | O19: =Results!T190 | P19: =Results!T208 | Q19: =Results!T226 | R19: =Results!T244 | S19: =Results!T262 | T19: =Results!T280 | U19: =Results!T298 | V19: =Results!T316 | W19: =Results!T334 | X19: =Results!T352
B20: ='Sample ID'!D20 -> G 7-12 | C20: ='Sample ID'!E20 -> 0 | D20: ='Sample ID'!F20 -> 0 | E20: =C20 & " - DF " & D20 -> 0 - DF 0 | F20: =Results!T29 | G20: =Results!T47 | H20: =Results!T65 | I20: =Results!T83 | J20: =Results!T101 | K20: =Results!T119 | L20: =Results!T137 | M20: =Results!T155 | N20: =Results!T173 | O20: =Results!T191 | P20: =Results!T209 | Q20: =Results!T227 | R20: =Results!T245 | S20: =Results!T263 | T20: =Results!T281 | U20: =Results!T299 | V20: =Results!T317 | W20: =Results!T335 | X20: =Results!T353
B21: ='Sample ID'!D21 -> H 7-12 | C21: ='Sample ID'!E21 -> 0 | D21: ='Sample ID'!F21 -> 0 | E21: =C21 & " - DF " & D21 -> 0 - DF 0 | F21: =Results!T30 | G21: =Results!T48 | H21: =Results!T66 | I21: =Results!T84 | J21: =Results!T102 | K21: =Results!T120 | L21: =Results!T138 | M21: =Results!T156 | N21: =Results!T174 | O21: =Results!T192 | P21: =Results!T210 | Q21: =Results!T228 | R21: =Results!T246 | S21: =Results!T264 | T21: =Results!T282 | U21: =Results!T300 | V21: =Results!T318 | W21: =Results!T336 | X21: =Results!T354
B23: No | C23: Sample ID | D23: Diluton Factor | E23: Graph Label | F23: 0 | G23: 5 | H23: 10 | I23: 15 | J23: 20 | K23: 25 | L23: 30 | M23: 35 | N23: 40 | O23: 45 | P23: 50 | Q23: 55 | R23: 60 | S23: 65 | T23: 70 | U23: 75 | V23: 80 | W23: 85 | X23: 90
B24: =B6 -> A 1-6 | C24: =C6 -> 484 | D24: =D6 -> 1 | E24: =E6 -> 484 - DF 1 | F24: =Results!U14 -> 0.014371548 | G24: =Results!U32 -> 0.010230736 | H24: =Results!U50 -> 0.013701891 | I24: =Results!U68 -> 0.0043064529 | J24: =Results!U86 -> 0.010915527 | K24: =Results!U104 -> 0.012958627 | L24: =Results!U122 -> 0.014841159 | M24: =Results!U140 -> 0.010620617 | N24: =Results!U158 -> 0.015714169 | O24: =Results!U176 -> 0.016309161 | P24: =Results!U194 -> 0.012721197 | Q24: =Results!U212 -> 0.01144941 | R24: =Results!U230 -> 0.010620617 | S24: =Results!U248 -> 0.013075726 | T24: =Results!U266 -> 0.0089598722 | U24: =Results!U284 | V24: =Results!U302 | W24: =Results!U320 | X24: =Results!U338
B25: =B7 -> B 1-6 | C25: =C7 -> 548 | D25: =D7 -> 1 | E25: =E7 -> 548 - DF 1 | F25: =Results!U15 -> 0.0054519417 | G25: =Results!U33 -> 0.0075268057 | H25: =Results!U51 -> 0.010118376 | I25: =Results!U69 -> 0.0046195313 | J25: =Results!U87 -> 0.0052622506 | K25: =Results!U105 -> 0.0034920374 | L25: =Results!U123 -> 0.0066677191 | M25: =Results!U141 -> 0.0097214208 | N25: =Results!U159 -> 0.010230736 | O25: =Results!U177 -> 0.016223261 | P25: =Results!U195 -> 0.0018173139 | Q25: =Results!U213 -> 0.0057247052 | R25: =Results!U231 -> 0.010938776 | S25: =Results!U249 -> 0.0090725794 | T25: =Results!U267 -> 0.0030241931 | U25: =Results!U285 | V25: =Results!U303 | W25: =Results!U321 | X25: =Results!U339
B26: =B8 -> C1-6 | C26: =C8 -> 716 | D26: =D8 -> 1 | E26: =E8 -> 716 - DF 1 | F26: =Results!U16 -> 0.021006717 | G26: =Results!U34 -> 0.014917991 | H26: =Results!U52 -> 0.01152681 | I26: =Results!U70 -> 0.015329541 | J26: =Results!U88 -> 0.014049756 | K26: =Results!U106 -> 0.0067810596 | L26: =Results!U124 -> 0.009603103 | M26: =Results!U142 -> 0.0020161288 | N26: =Results!U160 -> 0.0083279785 | O26: =Results!U178 -> 0.01084548 | P26: =Results!U196 -> 0.014406859 | Q26: =Results!U214 -> 0.017525541 | R26: =Results!U232 -> 0.024713002 | S26: =Results!U250 -> 0.019914056 | T26: =Results!U268 -> 0.012870104 | U26: =Results!U286 | V26: =Results!U304 | W26: =Results!U322 | X26: =Results!U340
B27: =B9 -> D 1-6 | C27: =C9 -> 824 | D27: =D9 -> 1 | E27: =E9 -> 824 - DF 1 | F27: =Results!U17 -> 0.0035282253 | G27: =Results!AE35 -> 0.00020161288 | H27: =Results!AE53 -> 0.0011625566 | I27: =Results!AE71 -> 0.00049499052 | J27: =Results!AE89 -> 0.0002557684 | K27: =Results!AE107 -> 0.00012263632 | L27: =Results!AE125 -> 0.00031116023 | M27: =Results!AE143 -> 0.00026436574 | N27: =Results!AE161 -> 0.00020279076 | O27: =Results!AE179 -> 8.8902922e-05 | P27: =Results!AE197 -> 0.00012096773 | Q27: =Results!U215 -> 0.00050403219 | R27: =Results!AE233 -> 9.6879713e-05 | S27: =Results!AE251 -> 0.00012309635 | T27: =Results!AE269 -> 0.00010655708 | U27: =Results!AE287 | V27: =Results!AE305 | W27: =Results!AE323 | X27: =Results!AE341
B28: =B10 -> E 1-6 | C28: =C10 -> 437 | D28: =D10 -> 1 | E28: =E10 -> 437 - DF 1 | F28: =Results!U18 -> 0.011625566 | G28: =Results!AE36 -> 0.0032005052 | H28: =Results!AE54 -> 0.00076107192 | I28: =Results!AE72 -> 0.00075660811 | J28: =Results!AE90 -> 0.00072034294 | K28: =Results!AE108 -> 0.00060718622 | L28: =Results!AE126 -> 0.00057247052 | M28: =Results!AE144 -> 0.00054704543 | N28: =Results!AE162 -> 0.00052622506 | O28: =Results!AE180 -> 0.0005248823 | P28: =Results!AE198 -> 0.00067630528 | Q28: =Results!U216 -> 0.027273684 | R28: =Results!AE234 -> 0.00058315699 | S28: =Results!AE252 -> 0.00069361272 | T28: =Results!AE270 -> 0.00071429868 | U28: =Results!AE288 | V28: =Results!AE306 | W28: =Results!AE324 | X28: =Results!AE342
B29: =B11 -> F 1-6 | C29: =C11 -> 0 | D29: =D11 -> 0 | E29: =E11 -> 0 - DF 0 | F29: =Results!U19 -> 0.019173109 | G29: =Results!AE37 -> 0.0008064515 | H29: =Results!AE55 -> 0.00049641414 | I29: =Results!AE73 -> 0.00054077536 | J29: =Results!AE91 -> 0.00053638593 | K29: =Results!AE109 -> 0.00068696463 | L29: =Results!AE127 -> 0.00057786899 | M29: =Results!AE145 -> 0.00041212806 | N29: =Results!AE163 -> 0.00024040803 | O29: =Results!AE181 -> 0.00018708883 | P29: =Results!AE199 -> 0.00025442395 | Q29: =Results!U217 -> 0.02772177 | R29: =Results!AE235 -> 0.00031510411 | S29: =Results!AE253 -> 0.00039714039 | T29: =Results!AE271 -> 0.00048607104 | U29: =Results!AE289 | V29: =Results!AE307 | W29: =Results!AE325 | X29: =Results!AE343
B30: =B12 -> G 1-6 | C30: =C12 -> 0 | D30: =D12 -> 0 | E30: =E12 -> 0 - DF 0 | F30: =Results!U20 -> 0.0052622506 | G30: =Results!AE38 -> 0.001322064 | H30: =Results!AE56 -> 0.00040322575 | I30: =Results!AE74 -> 0.00027504542 | J30: =Results!AE92 -> 0.00041639893 | K30: =Results!AE110 -> 2.0161288e-05 | L30: =Results!AE128 -> 0.00010492267 | M30: =Results!AE146 -> 2.8801839e-05 | N30: =Results!AE164 -> 0.0001485613 | O30: =Results!AE182 -> 9.9554135e-05 | P30: =Results!AE200 -> 0.00015120966 | Q30: =Results!U218 -> 0.012356501 | R30: =Results!AE236 -> 0.0001735885 | S30: =Results!AE254 -> 8.3876026e-05 | T30: =Results!AE272 -> 8.0180928e-05 | U30: =Results!AE290 | V30: =Results!AE308 | W30: =Results!AE326 | X30: =Results!AE344
B31: =B13 -> H 1-6 | C31: =C13 -> 0 | D31: =D13 -> 0 | E31: =E13 -> 0 - DF 0 | F31: =Results!U21 | G31: =Results!AE39 | H31: =Results!AE57 | I31: =Results!AE75 | J31: =Results!AE93 | K31: =Results!AE111 | L31: =Results!AE129 | M31: =Results!AE147 | N31: =Results!AE165 | O31: =Results!AE183 | P31: =Results!AE201 | Q31: =Results!U219 | R31: =Results!AE237 | S31: =Results!AE255 | T31: =Results!AE273 | U31: =Results!AE291 | V31: =Results!AE309 | W31: =Results!AE327 | X31: =Results!AE345
B32: =B14 -> A 7-12 | C32: =C14 -> 0 | D32: =D14 -> 0 | E32: =E14 -> 0 - DF 0 | F32: =Results!U23 | G32: =Results!U41 | H32: =Results!U59 | I32: =Results!U77 | J32: =Results!U95 | K32: =Results!U113 | L32: =Results!U131 | M32: =Results!U149 | N32: =Results!U167 | O32: =Results!U185 | P32: =Results!U203 | Q32: =Results!U221 | R32: =Results!U239 | S32: =Results!U257 | T32: =Results!U275 | U32: =Results!U293 | V32: =Results!U311 | W32: =Results!U329 | X32: =Results!U347
